<?xml version="1.0" encoding="utf-8"?>
<!-- =================================================================================== -->
<!-- |    This document was autogenerated by xacro from /mnt/d/Aditya_MT/MT_Thesis/Quadruped/ROS/quadroit_ws/src/quadroit_v1/urdf/quadroitv1.urdf.xacro | -->
<!-- |    EDITING THIS FILE BY HAND IS NOT RECOMMENDED                                 | -->
<!-- =================================================================================== -->
<robot name="quadroit_v1">
  <!-- <material name="red">
        <color rgba="1 0 0 1"/>
    </material>

    <material name="white">
        <color rgba="1 1 1 1"/>
    </material> -->
  <link name="base_link">
    <contact>
      <lateral_friction value="1"/>
    </contact>
    <inertial>
      <origin rpy="0 0 0" xyz="0 0 0"/>
      <mass value="0.2"/>
      <inertia ixx="1.0" ixy="0.0" ixz="0.0" iyy="1.0" iyz="0.0" izz="1.0"/>
    </inertial>
    <visual>
      <origin rpy="0 0 0" xyz="0 0 0"/>
      <geometry>
        <mesh filename="meshes/base_link_torso.STL" scale="0.20833 0.2381 0.3"/>
      </geometry>
      <material name="orange">
        <color rgba="0.92 0.59 0.30 1"/>
      </material>
    </visual>
    <collision>
      <origin rpy="0 0 0" xyz="0 0 0"/>
      <geometry>
        <mesh filename="meshes/base_link_torso.STL" scale="0.20833 0.2381 0.3"/>
      </geometry>
    </collision>
  </link>


  <link name="hip_link_FL">
    <contact>
      <lateral_friction value="1"/>
    </contact>
    <inertial>
      <origin rpy="0 0 0" xyz="0.0004 0 0"/>
      <mass value="0.001"/>
      <inertia ixx="1.0" ixy="0.0" ixz="0.0" iyy="1.0" iyz="0.0" izz="1.0"/>
    </inertial>
    <visual>
      <origin rpy="0 0 0" xyz="0 0 0"/>
      <geometry>
        <mesh filename="meshes/leg_fr_hip.STL" scale="0.01 0.01 0.3"/>
      </geometry>
      <material name="honey">
        <color rgba="0.99 0.89 0.65 1"/>
      </material>
    </visual>
    <collision>
      <origin rpy="0 0 0" xyz="0 0 0"/>
      <geometry>
        <mesh filename="meshes/leg_fr_hip.STL" scale="0.01 0.01 0.3"/>
      </geometry>
    </collision>
    <!-- <xacro:default_inertial mass="2"/> -->
  </link>
  <joint name="hip_joint_FL" type="revolute">
    <axis xyz="0 0 1"/>
    <limit effort="100" velocity="100"/>
    <joint_properties damping=".0" friction=".0"/>
    <parent link="base_link"/>
    <child link="hip_link_FL"/>
    <origin rpy="1.57075 1.57075 1.57075" xyz="0.0675 0.05 0"/>
  </joint>
  <link name="thigh_link_FL">
    <contact>
      <lateral_friction value="1"/>
    </contact>
    <inertial>
      <origin rpy="0 0 0" xyz="0.0225 0 0"/>
      <mass value="0.05"/>
      <inertia ixx="1.0" ixy="0.0" ixz="0.0" iyy="1.0" iyz="0.0" izz="1.0"/>
    </inertial>
    <visual>
      <origin rpy="0 0 0" xyz="0 0 0"/>
      <geometry>
        <mesh filename="meshes/leg_fr_thigh.STL" scale="0.225 0.225 0.225"/>
      </geometry>
      <material name="honey">
        <color rgba="0.99 0.89 0.65 1"/>
      </material>
    </visual>
    <collision>
      <origin rpy="0 0 0" xyz="0 0 0"/>
      <geometry>
        <mesh filename="meshes/leg_fr_thigh.STL" scale="0.225 0.225 0.225"/>
      </geometry>
    </collision>
    <!-- <xacro:default_inertial mass="2"/> -->
  </link>
  <joint name="elbow_joint_FL" type="revolute">
    <axis xyz="0 0 1"/>
    <limit effort="100" velocity="100"/>
    <joint_properties damping=".0" friction=".0"/>
    <parent link="hip_link_FL"/>
    <child link="thigh_link_FL"/>
    <origin rpy="1.57075 0 0" xyz="0.0008 0 0"/>
  </joint>
  <link name="shank_link_FL">
    <contact>
      <lateral_friction value="1"/>
    </contact>
    <inertial>
      <origin rpy="0 0 0" xyz="0.0275 0 0"/>
      <mass value="0.05"/>
      <inertia ixx="1.0" ixy="0.0" ixz="0.0" iyy="1.0" iyz="0.0" izz="1.0"/>
    </inertial>
    <visual>
      <origin rpy="0 0 0" xyz="0 0 0"/>
      <geometry>
        <mesh filename="meshes/leg_fr_shank.STL" scale="0.239 0.239 0.239"/>
      </geometry>
      <material name="honey">
        <color rgba="0.99 0.89 0.65 1"/>
      </material>
    </visual>
    <collision>
      <origin rpy="0 0 0" xyz="0 0 0"/>
      <geometry>
        <mesh filename="meshes/leg_fr_shank.STL" scale="0.239 0.239 0.239"/>
      </geometry>
    </collision>
  </link>
  <joint name="wrist_joint_FL" type="revolute">
    <axis xyz="0 0 1"/>
    <limit effort="100" velocity="100"/>
    <joint_properties damping=".0" friction=".0"/>
    <parent link="thigh_link_FL"/>
    <child link="shank_link_FL"/>
    <origin rpy="0 0 0" xyz="0.045 0 0"/>
  </joint>
  <link name="foot_link_FL">
    <contact>
      <friction_anchor/>
      <stiffness value="30000.0"/>
      <damping value="10000.0"/>
      <spinning_friction value="0.1"/>
      <lateral_friction value="10.0"/>
    </contact>
    <visual>
      <origin rpy="0 0 0" xyz="0 0 0"/>
      <geometry>
        <sphere radius="3e-6"/>
      </geometry>
      <material name="honey">
        <color rgba="0.99 0.89 0.65 1"/>
      </material>
    </visual>
    <collision>
      <origin rpy="0 0 0" xyz="0 0 0"/>
      <geometry>
        <sphere radius="3e-6"/>
      </geometry>
    </collision>
    <inertial>
      <mass value="0.01"/>
      <inertia ixx="0.000025" ixy="0" ixz="0" iyy="0.000025" iyz="0" izz="0.000025"/>
    </inertial>
  </link>
  <joint name="foot_FL" type="fixed">
    <parent link="shank_link_FL"/>
    <child link="foot_link_FL"/>
    <origin xyz="0.055 0 0"/>
    <dynamics damping="0.0" friction="0.0"/>
  </joint>

  
  <link name="hip_link_FR">
    <contact>
      <lateral_friction value="1"/>
    </contact>
    <inertial>
      <origin rpy="0 0 0" xyz="0.0004 0 0"/>
      <mass value="0.001"/>
      <inertia ixx="1.0" ixy="0.0" ixz="0.0" iyy="1.0" iyz="0.0" izz="1.0"/>
    </inertial>
    <visual>
      <origin rpy="0 0 0" xyz="0 0 0"/>
      <geometry>
        <mesh filename="meshes/leg_fr_hip.STL" scale="0.01 0.01 0.3"/>
      </geometry>
      <material name="honey">
        <color rgba="0.99 0.89 0.65 1"/>
      </material>
    </visual>
    <collision>
      <origin rpy="0 0 0" xyz="0 0 0"/>
      <geometry>
        <mesh filename="meshes/leg_fr_hip.STL" scale="0.01 0.01 0.3"/>
      </geometry>
    </collision>
    <!-- <xacro:default_inertial mass="2"/> -->
  </link>
  <joint name="hip_joint_FR" type="revolute">
    <axis xyz="0 0 1"/>
    <limit effort="100" velocity="100"/>
    <joint_properties damping=".0" friction=".0"/>
    <parent link="base_link"/>
    <child link="hip_link_FR"/>
    <origin rpy="1.57075 1.57075 1.57075" xyz="0.0675 -0.05 0"/>
  </joint>
  <link name="thigh_link_FR">
    <contact>
      <lateral_friction value="1"/>
    </contact>
    <inertial>
      <origin rpy="0 0 0" xyz="0.0225 0 0"/>
      <mass value="0.05"/>
      <inertia ixx="1.0" ixy="0.0" ixz="0.0" iyy="1.0" iyz="0.0" izz="1.0"/>
    </inertial>
    <visual>
      <origin rpy="0 0 0" xyz="0 0 0"/>
      <geometry>
        <mesh filename="meshes/leg_fr_thigh.STL" scale="0.225 0.225 0.225"/>
      </geometry>
      <material name="honey">
        <color rgba="0.99 0.89 0.65 1"/>
      </material>
    </visual>
    <collision>
      <origin rpy="0 0 0" xyz="0 0 0"/>
      <geometry>
        <mesh filename="meshes/leg_fr_thigh.STL" scale="0.225 0.225 0.225"/>
      </geometry>
    </collision>
    <!-- <xacro:default_inertial mass="2"/> -->
  </link>
  <joint name="elbow_joint_FR" type="revolute">
    <axis xyz="0 0 1"/>
    <limit effort="100" velocity="100"/>
    <joint_properties damping=".0" friction=".0"/>
    <parent link="hip_link_FR"/>
    <child link="thigh_link_FR"/>
    <origin rpy="1.57075 0 0" xyz="0.0008 0 0"/>
  </joint>
  <link name="shank_link_FR">
    <contact>
      <lateral_friction value="1"/>
    </contact>
    <inertial>
      <origin rpy="0 0 0" xyz="0.0275 0 0"/>
      <mass value="0.05"/>
      <inertia ixx="1.0" ixy="0.0" ixz="0.0" iyy="1.0" iyz="0.0" izz="1.0"/>
    </inertial>
    <visual>
      <origin rpy="0 0 0" xyz="0 0 0"/>
      <geometry>
        <mesh filename="meshes/leg_fr_shank.STL" scale="0.239 0.239 0.239"/>
      </geometry>
      <material name="honey">
        <color rgba="0.99 0.89 0.65 1"/>
      </material>
    </visual>
    <collision>
      <origin rpy="0 0 0" xyz="0 0 0"/>
      <geometry>
        <mesh filename="meshes/leg_fr_shank.STL" scale="0.239 0.239 0.239"/>
      </geometry>
    </collision>
    <!-- <xacro:default_inertial mass="2"/> -->
  </link>
  <joint name="wrist_joint_FR" type="revolute">
    <axis xyz="0 0 1"/>
    <limit effort="100" velocity="100"/>
    <joint_properties damping=".0" friction=".0"/>
    <parent link="thigh_link_FR"/>
    <child link="shank_link_FR"/>
    <origin rpy="0 0 0" xyz="0.045 0 0"/>
  </joint>
  <link name="foot_link_FR">
    <contact>
      <friction_anchor/>
      <stiffness value="30000.0"/>
      <damping value="10000.0"/>
      <spinning_friction value="0.1"/>
      <lateral_friction value="10.0"/>
    </contact>
    <visual>
      <origin rpy="0 0 0" xyz="0 0 0"/>
      <geometry>
        <sphere radius="3e-6"/>
      </geometry>
      <material name="honey">
        <color rgba="0.99 0.89 0.65 1"/>
      </material>
    </visual>
    <collision>
      <origin rpy="0 0 0" xyz="0 0 0"/>
      <geometry>
        <sphere radius="3e-6"/>
      </geometry>
    </collision>
    <inertial>
      <mass value="0.01"/>
      <inertia ixx="25e-10" ixy="0" ixz="0" iyy="25e-10" iyz="0" izz="25e-10"/>
    </inertial>
  </link>
  <joint name="foot_FR" type="fixed">
    <parent link="shank_link_FR"/>
    <child link="foot_link_FR"/>
    <origin xyz="0.055 0 0"/>
    <dynamics damping="0.0" friction="0.0"/>
  </joint>


  <link name="hip_link_RL">
    <contact>
      <lateral_friction value="1"/>
    </contact>
    <inertial>
      <origin rpy="0 0 0" xyz="0.0004 0 0"/>
      <mass value="0.001"/>
      <inertia ixx="1.0" ixy="0.0" ixz="0.0" iyy="1.0" iyz="0.0" izz="1.0"/>
    </inertial>
    <visual>
      <origin rpy="0 0 0" xyz="0 0 0"/>
      <geometry>
        <mesh filename="meshes/leg_fr_hip.STL" scale="0.01 0.01 0.3"/>
      </geometry>
      <material name="honey">
        <color rgba="0.99 0.89 0.65 1"/>
      </material>
    </visual>
    <collision>
      <origin rpy="0 0 0" xyz="0 0 0"/>
      <geometry>
        <mesh filename="meshes/leg_fr_hip.STL" scale="0.01 0.01 0.3"/>
      </geometry>
    </collision>
    <!-- <xacro:default_inertial mass="2"/> -->
  </link>
  <joint name="hip_joint_RL" type="revolute">
    <axis xyz="0 0 1"/>
    <limit effort="100" velocity="100"/>
    <joint_properties damping=".0" friction=".0"/>
    <parent link="base_link"/>
    <child link="hip_link_RL"/>
    <origin rpy="1.57075 1.57075 1.57075" xyz="-0.0675 0.05 0"/>
  </joint>
  <link name="thigh_link_RL">
    <contact>
      <lateral_friction value="1"/>
    </contact>
    <inertial>
      <origin rpy="0 0 0" xyz="0.0225 0 0"/>
      <mass value="0.05"/>
      <inertia ixx="1.0" ixy="0.0" ixz="0.0" iyy="1.0" iyz="0.0" izz="1.0"/>
    </inertial>
    <visual>
      <origin rpy="0 0 0" xyz="0 0 0"/>
      <geometry>
        <mesh filename="meshes/leg_fr_thigh.STL" scale="0.225 0.225 0.225"/>
      </geometry>
      <material name="honey">
        <color rgba="0.99 0.89 0.65 1"/>
      </material>
    </visual>
    <collision>
      <origin rpy="0 0 0" xyz="0 0 0"/>
      <geometry>
        <mesh filename="meshes/leg_fr_thigh.STL" scale="0.225 0.225 0.225"/>
      </geometry>
    </collision>
    <!-- <xacro:default_inertial mass="2"/> -->
  </link>
  <joint name="elbow_joint_RL" type="revolute">
    <axis xyz="0 0 1"/>
    <limit effort="100" velocity="100"/>
    <joint_properties damping=".0" friction=".0"/>
    <parent link="hip_link_RL"/>
    <child link="thigh_link_RL"/>
    <origin rpy="1.57075 0 0" xyz="0.0008 0 0"/>
  </joint>
  <link name="shank_link_RL">
    <contact>
      <lateral_friction value="1"/>
    </contact>
    <inertial>
      <origin rpy="0 0 0" xyz="0.0275 0 0"/>
      <mass value="0.05"/>
      <inertia ixx="1.0" ixy="0.0" ixz="0.0" iyy="1.0" iyz="0.0" izz="1.0"/>
    </inertial>
    <visual>
      <origin rpy="0 0 0" xyz="0 0 0"/>
      <geometry>
        <mesh filename="meshes/leg_fr_shank.STL" scale="0.239 0.239 0.239"/>
      </geometry>
      <material name="honey">
        <color rgba="0.99 0.89 0.65 1"/>
      </material>
    </visual>
    <collision>
      <origin rpy="0 0 0" xyz="0 0 0"/>
      <geometry>
        <mesh filename="meshes/leg_fr_shank.STL" scale="0.239 0.239 0.239"/>
      </geometry>
    </collision>
    <!-- <xacro:default_inertial mass="2"/> -->
  </link>
  <joint name="wrist_joint_RL" type="revolute">
    <axis xyz="0 0 1"/>
    <limit effort="100" velocity="100"/>
    <joint_properties damping=".0" friction=".0"/>
    <parent link="thigh_link_RL"/>
    <child link="shank_link_RL"/>
    <origin rpy="0 0 0" xyz="0.045 0 0"/>
  </joint>
  <link name="foot_link_RL">
    <contact>
      <friction_anchor/>
      <stiffness value="30000.0"/>
      <damping value="10000.0"/>
      <spinning_friction value="0.1"/>
      <lateral_friction value="10.0"/>
    </contact>
    <visual>
      <origin rpy="0 0 0" xyz="0 0 0"/>
      <geometry>
        <sphere radius="3e-6"/>
      </geometry>
      <material name="honey">
        <color rgba="0.99 0.89 0.65 1"/>
      </material>
    </visual>
    <collision>
      <origin rpy="0 0 0" xyz="0 0 0"/>
      <geometry>
        <sphere radius="3e-6"/>
      </geometry>
    </collision>
    <inertial>
      <mass value="0.01"/>
      <inertia ixx="0.000025" ixy="0" ixz="0" iyy="0.000025" iyz="0" izz="0.000025"/>
    </inertial>
  </link>
  <joint name="foot_RL" type="fixed">
    <parent link="shank_link_RL"/>
    <child link="foot_link_RL"/>
    <origin xyz="0.055 0 0"/>
    <dynamics damping="0.0" friction="0.0"/>
  </joint>


  <link name="hip_link_RR">
    <contact>
      <lateral_friction value="1"/>
    </contact>
    <inertial>
      <origin rpy="0 0 0" xyz="0.0004 0 0"/>
      <mass value="0.001"/>
      <inertia ixx="1.0" ixy="0.0" ixz="0.0" iyy="1.0" iyz="0.0" izz="1.0"/>
    </inertial>
    <visual>
      <origin rpy="0 0 0" xyz="0 0 0"/>
      <geometry>
        <mesh filename="meshes/leg_fr_hip.STL" scale="0.01 0.01 0.3"/>
      </geometry>
      <material name="honey">
        <color rgba="0.99 0.89 0.65 1"/>
      </material>
    </visual>
    <collision>
      <origin rpy="0 0 0" xyz="0 0 0"/>
      <geometry>
        <mesh filename="meshes/leg_fr_hip.STL" scale="0.01 0.01 0.3"/>
      </geometry>
    </collision>
    <!-- <xacro:default_inertial mass="2"/> -->
  </link>
  <joint name="hip_joint_RR" type="revolute">
    <axis xyz="0 0 1"/>
    <limit effort="100" velocity="100"/>
    <joint_properties damping=".0" friction=".0"/>
    <parent link="base_link"/>
    <child link="hip_link_RR"/>
    <origin rpy="1.57075 1.57075 1.57075" xyz="-0.0675 -0.05 0"/>
  </joint>
  <link name="thigh_link_RR">
    <contact>
      <lateral_friction value="1"/>
    </contact>
    <inertial>
      <origin rpy="0 0 0" xyz="0.0225 0 0"/>
      <mass value="0.05"/>
      <inertia ixx="1.0" ixy="0.0" ixz="0.0" iyy="1.0" iyz="0.0" izz="1.0"/>
    </inertial>
    <visual>
      <origin rpy="0 0 0" xyz="0 0 0"/>
      <geometry>
        <mesh filename="meshes/leg_fr_thigh.STL" scale="0.225 0.225 0.225"/>
      </geometry>
      <material name="honey">
        <color rgba="0.99 0.89 0.65 1"/>
      </material>
    </visual>
    <collision>
      <origin rpy="0 0 0" xyz="0 0 0"/>
      <geometry>
        <mesh filename="meshes/leg_fr_thigh.STL" scale="0.225 0.225 0.225"/>
      </geometry>
    </collision>
    <!-- <xacro:default_inertial mass="2"/> -->
  </link>
  <joint name="elbow_joint_RR" type="revolute">
    <axis xyz="0 0 1"/>
    <limit effort="100" velocity="100"/>
    <joint_properties damping=".0" friction=".0"/>
    <parent link="hip_link_RR"/>
    <child link="thigh_link_RR"/>
    <origin rpy="1.57075 0 0" xyz="0.0008 0 0"/>
  </joint>
  <link name="shank_link_RR">
    <contact>
      <lateral_friction value="1"/>
    </contact>
    <inertial>
      <origin rpy="0 0 0" xyz="0.0275 0 0"/>
      <mass value="0.05"/>
      <inertia ixx="1.0" ixy="0.0" ixz="0.0" iyy="1.0" iyz="0.0" izz="1.0"/>
    </inertial>
    <visual>
      <origin rpy="0 0 0" xyz="0 0 0"/>
      <geometry>
        <mesh filename="meshes/leg_fr_shank.STL" scale="0.239 0.239 0.239"/>
      </geometry>
      <material name="honey">
        <color rgba="0.99 0.89 0.65 1"/>
      </material>
    </visual>
    <collision>
      <origin rpy="0 0 0" xyz="0 0 0"/>
      <geometry>
        <mesh filename="meshes/leg_fr_shank.STL" scale="0.239 0.239 0.239"/>
      </geometry>
    </collision>
    <!-- <xacro:default_inertial mass="2"/> -->
  </link>
  <joint name="wrist_joint_RR" type="revolute">
    <axis xyz="0 0 1"/>
    <limit effort="100" velocity="100"/>
    <joint_properties damping=".0" friction=".0"/>
    <parent link="thigh_link_RR"/>
    <child link="shank_link_RR"/>
    <origin rpy="0 0 0" xyz="0.045 0 0"/>
  </joint>
  <link name="foot_link_RR">
    <contact>
      <friction_anchor/>
      <stiffness value="30000.0"/>
      <damping value="10000.0"/>
      <spinning_friction value="0.1"/>
      <lateral_friction value="10.0"/>
    </contact>
    <visual>
      <origin rpy="0 0 0" xyz="0 0 0"/>
      <geometry>
        <sphere radius="3e-6"/>
      </geometry>
      <material name="honey">
        <color rgba="0.99 0.89 0.65 1"/>
      </material>
    </visual>
    <collision>
      <origin rpy="0 0 0" xyz="0 0 0"/>
      <geometry>
        <sphere radius="3e-6"/>
      </geometry>
    </collision>
    <inertial>
      <mass value="0.01"/>
      <inertia ixx="0.000025" ixy="0" ixz="0" iyy="0.000025" iyz="0" izz="0.000025"/>
    </inertial>
  </link>
  <joint name="foot_RR" type="fixed">
    <parent link="shank_link_RR"/>
    <child link="foot_link_RR"/>
    <origin xyz="0.055 0 0"/>
    <dynamics damping="0.0" friction="0.0"/>
  </joint>
</robot>
