<?xml version="1.0" encoding="utf-8"?>
<!-- =================================================================================== -->
<!-- |    This document was autogenerated by xacro from /mnt/d/Aditya_MT/MT_Thesis/Quadruped/ROS/quadroit_ws/src/quadroit_v1/urdf/quadroitv1.urdf.xacro | -->
<!-- |    EDITING THIS FILE BY HAND IS NOT RECOMMENDED                                 | -->
<!-- =================================================================================== -->
<robot name="quadroit_v1">
  <!-- <material name="red">
        <color rgba="1 0 0 1"/>
    </material>

    <material name="white">
        <color rgba="1 1 1 1"/>
    </material> -->
  <link name="base_link">
    <inertial>
      <origin rpy="0 0 0" xyz="0 0 0"/>
      <mass value="10"/>
      <inertia ixx="1.0" ixy="0.0" ixz="0.0" iyy="1.0" iyz="0.0" izz="1.0"/>
    </inertial>
    <visual>
      <origin rpy="0 0 0" xyz="0 0 0"/>
      <geometry>
        <mesh filename="package://quadroit_v1/meshes/base_link_torso.STL"/>
      </geometry>
      <material name="">
        <color rgba="1 0.95686 0.93725 1"/>
      </material>
    </visual>
    <collision>
      <origin rpy="0 0 0" xyz="0 0 0"/>
      <geometry>
        <mesh filename="package://quadroit_v1/meshes/base_link_torso.STL"/>
      </geometry>
    </collision>
    <!-- <xacro:default_inertial mass="10" /> -->
  </link>
  <link name="hip_link_lf">
    <inertial>
      <origin rpy="0 0 0" xyz="0.04 0 0"/>
      <mass value="2"/>
      <inertia ixx="1.0" ixy="0.0" ixz="0.0" iyy="1.0" iyz="0.0" izz="1.0"/>
    </inertial>
    <visual>
      <origin rpy="0 0 0" xyz="0 0 0"/>
      <geometry>
        <mesh filename="package://quadroit_v1/meshes/leg_fr_hip.STL"/>
      </geometry>
      <material name="">
        <color rgba="0.66667 0.69804 0.76863 1"/>
      </material>
    </visual>
    <collision>
      <origin rpy="0 0 0" xyz="0 0 0"/>
      <geometry>
        <mesh filename="package://quadroit_v1/meshes/leg_fr_hip.STL"/>
      </geometry>
    </collision>
    <!-- <xacro:default_inertial mass="2"/> -->
  </link>
  <joint name="hip_joint_lf" type="revolute">
    <axis xyz="0 0 1"/>
    <limit effort="1000.0" lower="-1.57075" upper="1.57075" velocity="0.5"/>
    <parent link="base_link"/>
    <child link="hip_link_lf"/>
    <origin rpy="1.57075 1.57075 1.57075" xyz="0.3 0.21 0"/>
  </joint>
  <link name="thigh_link_lf">
    <inertial>
      <origin rpy="0 0 0" xyz="0.1 0 0"/>
      <mass value="2"/>
      <inertia ixx="1.0" ixy="0.0" ixz="0.0" iyy="1.0" iyz="0.0" izz="1.0"/>
    </inertial>
    <visual>
      <origin rpy="0 0 0" xyz="0 0 0"/>
      <geometry>
        <mesh filename="package://quadroit_v1/meshes/leg_fr_thigh.STL"/>
      </geometry>
      <material name="">
        <color rgba="0.66667 0.69804 0.76863 1"/>
      </material>
    </visual>
    <collision>
      <origin rpy="0 0 0" xyz="0 0 0"/>
      <geometry>
        <mesh filename="package://quadroit_v1/meshes/leg_fr_thigh.STL"/>
      </geometry>
    </collision>
    <!-- <xacro:default_inertial mass="2"/> -->
  </link>
  <joint name="elbow_joint_lf" type="revolute">
    <axis xyz="0 0 1"/>
    <limit effort="1000.0" lower="-1.57075" upper="1.57075" velocity="0.5"/>
    <parent link="hip_link_lf"/>
    <child link="thigh_link_lf"/>
    <origin rpy="1.57075 0 0" xyz="0.08 0 0"/>
  </joint>
  <link name="shank_link_lf">
    <inertial>
      <origin rpy="0 0 0" xyz="0.11 0 0"/>
      <mass value="2"/>
      <inertia ixx="1.0" ixy="0.0" ixz="0.0" iyy="1.0" iyz="0.0" izz="1.0"/>
    </inertial>
    <visual>
      <origin rpy="0 0 0" xyz="0 0 0"/>
      <geometry>
        <mesh filename="package://quadroit_v1/meshes/leg_fr_shank.STL"/>
      </geometry>
      <material name="">
        <color rgba="0.66667 0.69804 0.76863 1"/>
      </material>
    </visual>
    <collision>
      <origin rpy="0 0 0" xyz="0 0 0"/>
      <geometry>
        <mesh filename="package://quadroit_v1/meshes/leg_fr_shank.STL"/>
      </geometry>
    </collision>
    <!-- <xacro:default_inertial mass="2"/> -->
  </link>
  <joint name="wrist_joint_lf" type="revolute">
    <axis xyz="0 0 1"/>
    <limit effort="1000.0" lower="-1.57075" upper="1.57075" velocity="0.5"/>
    <parent link="thigh_link_lf"/>
    <child link="shank_link_lf"/>
    <origin rpy="0 0 0" xyz="0.2 0 0"/>
  </joint>
  <link name="foot_link_lf">
    <!-- <visual>
                <geometry>
                    <sphere radius="${foot_radius}"/>
                </geometry>
                <origin rpy="0 0 0" xyz="0 0 0"/>
                <material name="white"/>
            </visual>
            <xacro:default_inertial mass="0.2"/> -->
  </link>
  <joint name="foot_lf" type="fixed">
    <parent link="shank_link_lf"/>
    <child link="foot_link_lf"/>
    <origin xyz="0.23 0 0"/>
  </joint>
  <link name="hip_link_rf">
    <inertial>
      <origin rpy="0 0 0" xyz="0.04 0 0"/>
      <mass value="2"/>
      <inertia ixx="1.0" ixy="0.0" ixz="0.0" iyy="1.0" iyz="0.0" izz="1.0"/>
    </inertial>
    <visual>
      <origin rpy="0 0 0" xyz="0 0 0"/>
      <geometry>
        <mesh filename="package://quadroit_v1/meshes/leg_fr_hip.STL"/>
      </geometry>
      <material name="">
        <color rgba="0.66667 0.69804 0.76863 1"/>
      </material>
    </visual>
    <collision>
      <origin rpy="0 0 0" xyz="0 0 0"/>
      <geometry>
        <mesh filename="package://quadroit_v1/meshes/leg_fr_hip.STL"/>
      </geometry>
    </collision>
    <!-- <xacro:default_inertial mass="2"/> -->
  </link>
  <joint name="hip_joint_rf" type="revolute">
    <axis xyz="0 0 1"/>
    <limit effort="1000.0" lower="-1.57075" upper="1.57075" velocity="0.5"/>
    <parent link="base_link"/>
    <child link="hip_link_rf"/>
    <origin rpy="1.57075 1.57075 1.57075" xyz="0.3 -0.21 0"/>
  </joint>
  <link name="thigh_link_rf">
    <inertial>
      <origin rpy="0 0 0" xyz="0.1 0 0"/>
      <mass value="2"/>
      <inertia ixx="1.0" ixy="0.0" ixz="0.0" iyy="1.0" iyz="0.0" izz="1.0"/>
    </inertial>
    <visual>
      <origin rpy="0 0 0" xyz="0 0 0"/>
      <geometry>
        <mesh filename="package://quadroit_v1/meshes/leg_fr_thigh.STL"/>
      </geometry>
      <material name="">
        <color rgba="0.66667 0.69804 0.76863 1"/>
      </material>
    </visual>
    <collision>
      <origin rpy="0 0 0" xyz="0 0 0"/>
      <geometry>
        <mesh filename="package://quadroit_v1/meshes/leg_fr_thigh.STL"/>
      </geometry>
    </collision>
    <!-- <xacro:default_inertial mass="2"/> -->
  </link>
  <joint name="elbow_joint_rf" type="revolute">
    <axis xyz="0 0 1"/>
    <limit effort="1000.0" lower="-1.57075" upper="1.57075" velocity="0.5"/>
    <parent link="hip_link_rf"/>
    <child link="thigh_link_rf"/>
    <origin rpy="1.57075 0 0" xyz="0.08 0 0"/>
  </joint>
  <link name="shank_link_rf">
    <inertial>
      <origin rpy="0 0 0" xyz="0.11 0 0"/>
      <mass value="2"/>
      <inertia ixx="1.0" ixy="0.0" ixz="0.0" iyy="1.0" iyz="0.0" izz="1.0"/>
    </inertial>
    <visual>
      <origin rpy="0 0 0" xyz="0 0 0"/>
      <geometry>
        <mesh filename="package://quadroit_v1/meshes/leg_fr_shank.STL"/>
      </geometry>
      <material name="">
        <color rgba="0.66667 0.69804 0.76863 1"/>
      </material>
    </visual>
    <collision>
      <origin rpy="0 0 0" xyz="0 0 0"/>
      <geometry>
        <mesh filename="package://quadroit_v1/meshes/leg_fr_shank.STL"/>
      </geometry>
    </collision>
    <!-- <xacro:default_inertial mass="2"/> -->
  </link>
  <joint name="wrist_joint_rf" type="revolute">
    <axis xyz="0 0 1"/>
    <limit effort="1000.0" lower="-1.57075" upper="1.57075" velocity="0.5"/>
    <parent link="thigh_link_rf"/>
    <child link="shank_link_rf"/>
    <origin rpy="0 0 0" xyz="0.2 0 0"/>
  </joint>
  <link name="foot_link_rf">
    <!-- <visual>
                <geometry>
                    <sphere radius="${foot_radius}"/>
                </geometry>
                <origin rpy="0 0 0" xyz="0 0 0"/>
                <material name="white"/>
            </visual>
            <xacro:default_inertial mass="0.2"/> -->
  </link>
  <joint name="foot_rf" type="fixed">
    <parent link="shank_link_rf"/>
    <child link="foot_link_rf"/>
    <origin xyz="0.23 0 0"/>
  </joint>
  <link name="hip_link_lb">
    <inertial>
      <origin rpy="0 0 0" xyz="0.04 0 0"/>
      <mass value="2"/>
      <inertia ixx="1.0" ixy="0.0" ixz="0.0" iyy="1.0" iyz="0.0" izz="1.0"/>
    </inertial>
    <visual>
      <origin rpy="0 0 0" xyz="0 0 0"/>
      <geometry>
        <mesh filename="package://quadroit_v1/meshes/leg_fr_hip.STL"/>
      </geometry>
      <material name="">
        <color rgba="0.66667 0.69804 0.76863 1"/>
      </material>
    </visual>
    <collision>
      <origin rpy="0 0 0" xyz="0 0 0"/>
      <geometry>
        <mesh filename="package://quadroit_v1/meshes/leg_fr_hip.STL"/>
      </geometry>
    </collision>
    <!-- <xacro:default_inertial mass="2"/> -->
  </link>
  <joint name="hip_joint_lb" type="revolute">
    <axis xyz="0 0 1"/>
    <limit effort="1000.0" lower="-1.57075" upper="1.57075" velocity="0.5"/>
    <parent link="base_link"/>
    <child link="hip_link_lb"/>
    <origin rpy="1.57075 1.57075 1.57075" xyz="-0.3 0.21 0"/>
  </joint>
  <link name="thigh_link_lb">
    <inertial>
      <origin rpy="0 0 0" xyz="0.1 0 0"/>
      <mass value="2"/>
      <inertia ixx="1.0" ixy="0.0" ixz="0.0" iyy="1.0" iyz="0.0" izz="1.0"/>
    </inertial>
    <visual>
      <origin rpy="0 0 0" xyz="0 0 0"/>
      <geometry>
        <mesh filename="package://quadroit_v1/meshes/leg_fr_thigh.STL"/>
      </geometry>
      <material name="">
        <color rgba="0.66667 0.69804 0.76863 1"/>
      </material>
    </visual>
    <collision>
      <origin rpy="0 0 0" xyz="0 0 0"/>
      <geometry>
        <mesh filename="package://quadroit_v1/meshes/leg_fr_thigh.STL"/>
      </geometry>
    </collision>
    <!-- <xacro:default_inertial mass="2"/> -->
  </link>
  <joint name="elbow_joint_lb" type="revolute">
    <axis xyz="0 0 1"/>
    <limit effort="1000.0" lower="-1.57075" upper="1.57075" velocity="0.5"/>
    <parent link="hip_link_lb"/>
    <child link="thigh_link_lb"/>
    <origin rpy="1.57075 0 0" xyz="0.08 0 0"/>
  </joint>
  <link name="shank_link_lb">
    <inertial>
      <origin rpy="0 0 0" xyz="0.11 0 0"/>
      <mass value="2"/>
      <inertia ixx="1.0" ixy="0.0" ixz="0.0" iyy="1.0" iyz="0.0" izz="1.0"/>
    </inertial>
    <visual>
      <origin rpy="0 0 0" xyz="0 0 0"/>
      <geometry>
        <mesh filename="package://quadroit_v1/meshes/leg_fr_shank.STL"/>
      </geometry>
      <material name="">
        <color rgba="0.66667 0.69804 0.76863 1"/>
      </material>
    </visual>
    <collision>
      <origin rpy="0 0 0" xyz="0 0 0"/>
      <geometry>
        <mesh filename="package://quadroit_v1/meshes/leg_fr_shank.STL"/>
      </geometry>
    </collision>
    <!-- <xacro:default_inertial mass="2"/> -->
  </link>
  <joint name="wrist_joint_lb" type="revolute">
    <axis xyz="0 0 1"/>
    <limit effort="1000.0" lower="-1.57075" upper="1.57075" velocity="0.5"/>
    <parent link="thigh_link_lb"/>
    <child link="shank_link_lb"/>
    <origin rpy="0 0 0" xyz="0.2 0 0"/>
  </joint>
  <link name="foot_link_lb">
    <!-- <visual>
                <geometry>
                    <sphere radius="${foot_radius}"/>
                </geometry>
                <origin rpy="0 0 0" xyz="0 0 0"/>
                <material name="white"/>
            </visual>
            <xacro:default_inertial mass="0.2"/> -->
  </link>
  <joint name="foot_lb" type="fixed">
    <parent link="shank_link_lb"/>
    <child link="foot_link_lb"/>
    <origin xyz="0.23 0 0"/>
  </joint>
  <link name="hip_link_rb">
    <inertial>
      <origin rpy="0 0 0" xyz="0.04 0 0"/>
      <mass value="2"/>
      <inertia ixx="1.0" ixy="0.0" ixz="0.0" iyy="1.0" iyz="0.0" izz="1.0"/>
    </inertial>
    <visual>
      <origin rpy="0 0 0" xyz="0 0 0"/>
      <geometry>
        <mesh filename="package://quadroit_v1/meshes/leg_fr_hip.STL"/>
      </geometry>
      <material name="">
        <color rgba="0.66667 0.69804 0.76863 1"/>
      </material>
    </visual>
    <collision>
      <origin rpy="0 0 0" xyz="0 0 0"/>
      <geometry>
        <mesh filename="package://quadroit_v1/meshes/leg_fr_hip.STL"/>
      </geometry>
    </collision>
    <!-- <xacro:default_inertial mass="2"/> -->
  </link>
  <joint name="hip_joint_rb" type="revolute">
    <axis xyz="0 0 1"/>
    <limit effort="1000.0" lower="-1.57075" upper="1.57075" velocity="0.5"/>
    <parent link="base_link"/>
    <child link="hip_link_rb"/>
    <origin rpy="1.57075 1.57075 1.57075" xyz="-0.3 -0.21 0"/>
  </joint>
  <link name="thigh_link_rb">
    <inertial>
      <origin rpy="0 0 0" xyz="0.1 0 0"/>
      <mass value="2"/>
      <inertia ixx="1.0" ixy="0.0" ixz="0.0" iyy="1.0" iyz="0.0" izz="1.0"/>
    </inertial>
    <visual>
      <origin rpy="0 0 0" xyz="0 0 0"/>
      <geometry>
        <mesh filename="package://quadroit_v1/meshes/leg_fr_thigh.STL"/>
      </geometry>
      <material name="">
        <color rgba="0.66667 0.69804 0.76863 1"/>
      </material>
    </visual>
    <collision>
      <origin rpy="0 0 0" xyz="0 0 0"/>
      <geometry>
        <mesh filename="package://quadroit_v1/meshes/leg_fr_thigh.STL"/>
      </geometry>
    </collision>
    <!-- <xacro:default_inertial mass="2"/> -->
  </link>
  <joint name="elbow_joint_rb" type="revolute">
    <axis xyz="0 0 1"/>
    <limit effort="1000.0" lower="-1.57075" upper="1.57075" velocity="0.5"/>
    <parent link="hip_link_rb"/>
    <child link="thigh_link_rb"/>
    <origin rpy="1.57075 0 0" xyz="0.08 0 0"/>
  </joint>
  <link name="shank_link_rb">
    <inertial>
      <origin rpy="0 0 0" xyz="0.11 0 0"/>
      <mass value="2"/>
      <inertia ixx="1.0" ixy="0.0" ixz="0.0" iyy="1.0" iyz="0.0" izz="1.0"/>
    </inertial>
    <visual>
      <origin rpy="0 0 0" xyz="0 0 0"/>
      <geometry>
        <mesh filename="package://quadroit_v1/meshes/leg_fr_shank.STL"/>
      </geometry>
      <material name="">
        <color rgba="0.66667 0.69804 0.76863 1"/>
      </material>
    </visual>
    <collision>
      <origin rpy="0 0 0" xyz="0 0 0"/>
      <geometry>
        <mesh filename="package://quadroit_v1/meshes/leg_fr_shank.STL"/>
      </geometry>
    </collision>
    <!-- <xacro:default_inertial mass="2"/> -->
  </link>
  <joint name="wrist_joint_rb" type="revolute">
    <axis xyz="0 0 1"/>
    <limit effort="1000.0" lower="-1.57075" upper="1.57075" velocity="0.5"/>
    <parent link="thigh_link_rb"/>
    <child link="shank_link_rb"/>
    <origin rpy="0 0 0" xyz="0.2 0 0"/>
  </joint>
  <link name="foot_link_rb">
    <!-- <visual>
                <geometry>
                    <sphere radius="${foot_radius}"/>
                </geometry>
                <origin rpy="0 0 0" xyz="0 0 0"/>
                <material name="white"/>
            </visual>
            <xacro:default_inertial mass="0.2"/> -->
  </link>
  <joint name="foot_rb" type="fixed">
    <parent link="shank_link_rb"/>
    <child link="foot_link_rb"/>
    <origin xyz="0.23 0 0"/>
  </joint>
</robot>
